<?xml version="1.0" ?>
<!-- =================================================================================== -->
<!-- |    This document was autogenerated by xacro from /opt/ros/noetic/share/franka_description/robots/panda_arm.urdf.xacro | -->
<!-- |    EDITING THIS FILE BY HAND IS NOT RECOMMENDED                                 | -->
<!-- =================================================================================== -->
<robot name="panda">
  <!-- Is the robot being simulated in gazebo?" -->
  <!-- =============================================================== -->
  <!-- || This file does not contain official inertial properties   || -->
  <!-- || of panda robot. The values are from the identification    || -->
  <!-- || results published in: Identification of the Franka Emika  || -->
  <!-- || PandaRobot With Retrieval of Feasible Parameters Using    || -->
  <!-- || Penalty-Based Optimization                                || -->
  <!-- || by: Claudio Gaz, Marco Cognetti, Alexander Oliva,         || -->
  <!-- || Paolo Robuffo Giordano, Alessandro de Lucaa               || -->
  <!-- =============================================================== -->
  <link name="panda_link0">
    <visual>
      <origin rpy="0 0 0" xyz="0 0 0"/>
      <geometry>
        <mesh filename="visual/link0.dae"/>
      </geometry>
    </visual>
    <collision>
      <origin rpy="0 0 0" xyz="0 0 0"/>
      <geometry>
        <mesh filename="collision/link0.stl"/>
      </geometry>
    </collision>
    <inertial>
      <!-- Estimated guesses from CAD -->
      <origin rpy="0 0 0" xyz="-0.041018 -0.00014 0.049974"/>
      <mass value="0.629769"/>
      <inertia ixx="0.00315" ixy="8.2904E-07" ixz="0.00015" iyy="0.00388" iyz="8.2299E-06" izz="0.004285"/>
    </inertial>
  </link>
  <link name="panda_link1">
    <visual>
      <origin rpy="0 0 0" xyz="0 0 0"/>
      <geometry>
        <mesh filename="visual/link1.dae"/>
      </geometry>
    </visual>
    <collision>
      <origin rpy="0 0 0" xyz="0 0 0"/>
      <geometry>
        <mesh filename="collision/link1.stl"/>
      </geometry>
    </collision>
    <inertial>
      <origin rpy="0 0 0" xyz="0.00821216 -0.0265777 -0.0476148"/>
      <mass value="4.97068"/>
      <inertia ixx="0.703435" ixy="-0.000118671" ixz="0.00679074" iyy="0.706505" iyz="0.019157" izz="0.00914644"/>
    </inertial>
  </link>
  <joint name="panda_joint1" type="revolute">
    <safety_controller k_position="100.0" k_velocity="40.0" soft_lower_limit="-2.8973" soft_upper_limit="2.8973"/>
    <origin rpy="0 0 0" xyz="0 0 0.333"/>
    <parent link="panda_link0"/>
    <child link="panda_link1"/>
    <axis xyz="0 0 1"/>
    <limit acceleration="15" effort="87" lower="-2.9671" upper="2.9671" velocity="2.5"/>
    <dynamics D="1" K="7000" damping="0.003" friction="0.0" mu_coulomb="0" mu_viscous="16"/>
  </joint>
  <link name="panda_link2">
    <visual>
      <origin rpy="0 0 0" xyz="0 0 0"/>
      <geometry>
        <mesh filename="visual/link2.dae"/>
      </geometry>
    </visual>
    <collision>
      <origin rpy="0 0 0" xyz="0 0 0"/>
      <geometry>
        <mesh filename="collision/link2.stl"/>
      </geometry>
    </collision>
    <inertial>
      <origin rpy="0 0 0" xyz="-0.00885572 -0.0153876 -0.000210413"/>
      <mass value="0.646303"/>
      <inertia ixx="0.00796321" ixy="-0.00390696" ixz="0.0102439" iyy="0.0281194" iyz="0.000678074" izz="0.0259687"/>
    </inertial>
  </link>
  <joint name="panda_joint2" type="revolute">
    <safety_controller k_position="100.0" k_velocity="40.0" soft_lower_limit="-1.7628" soft_upper_limit="1.7628"/>
    <origin rpy="-1.5707963267948966 0 0" xyz="0 0 0"/>
    <parent link="panda_link1"/>
    <child link="panda_link2"/>
    <axis xyz="0 0 1"/>
    <limit acceleration="7.5" effort="87" lower="-1.8326" upper="1.8326" velocity="2.5"/>
    <dynamics D="1" K="7000" damping="0.003" friction="0.0" mu_coulomb="0" mu_viscous="16"/>
  </joint>
  <link name="panda_link3">
    <visual>
      <origin rpy="0 0 0" xyz="0 0 0"/>
      <geometry>
        <mesh filename="visual/link3.dae"/>
      </geometry>
    </visual>
    <collision>
      <origin rpy="0 0 0" xyz="0 0 0"/>
      <geometry>
        <mesh filename="collision/link3.stl"/>
      </geometry>
    </collision>
    <inertial>
      <origin rpy="0 0 0" xyz="0.0104185 0.0386205 -0.133194"/>
      <mass value="3.22332"/>
      <inertia ixx="0.0372421" ixy="-0.00476086" ixz="-0.0113964" iyy="0.0361549" iyz="-0.012805" izz="0.0108299"/>
    </inertial>
  </link>
  <joint name="panda_joint3" type="revolute">
    <safety_controller k_position="100.0" k_velocity="40.0" soft_lower_limit="-2.8973" soft_upper_limit="2.8973"/>
    <origin rpy="1.5707963267948966 0 0" xyz="0 -0.316 0"/>
    <parent link="panda_link2"/>
    <child link="panda_link3"/>
    <axis xyz="0 0 1"/>
    <limit acceleration="12.5" effort="87" lower="-2.9671" upper="2.9671" velocity="2.5"/>
    <dynamics D="1" K="7000" damping="0.003" friction="0.0" mu_coulomb="0" mu_viscous="16"/>
  </joint>
  <link name="panda_link4">
    <visual>
      <origin rpy="0 0 0" xyz="0 0 0"/>
      <geometry>
        <mesh filename="visual/link4.dae"/>
      </geometry>
    </visual>
    <collision>
      <origin rpy="0 0 0" xyz="0 0 0"/>
      <geometry>
        <mesh filename="collision/link4.stl"/>
      </geometry>
    </collision>
    <inertial>
      <origin rpy="0 0 0" xyz="-0.0366071 0.0354336 0.0281498"/>
      <mass value="3.57869"/>
      <inertia ixx="0.0258529" ixy="0.007796" ixz="-0.001332" iyy="0.019552" iyz="0.008641" izz="0.028323"/>
    </inertial>
  </link>
  <joint name="panda_joint4" type="revolute">
    <safety_controller k_position="100.0" k_velocity="40.0" soft_lower_limit="-3.0718" soft_upper_limit="-0.0698"/>
    <origin rpy="1.5707963267948966 0 0" xyz="0.0825 0 0"/>
    <parent link="panda_link3"/>
    <child link="panda_link4"/>
    <axis xyz="0 0 1"/>
    <limit acceleration="12.5" effort="87" lower="-3.1416" upper="-0.4" velocity="2.5"/>
    <dynamics D="1" K="7000" damping="0.003" friction="0.0" mu_coulomb="0" mu_viscous="16"/>
  </joint>
  <link name="panda_link5">
    <visual>
      <origin rpy="0 0 0" xyz="0 0 0"/>
      <geometry>
        <mesh filename="visual/link5.dae"/>
      </geometry>
    </visual>
    <collision>
      <origin rpy="0 0 0" xyz="0 0 0"/>
      <geometry>
        <mesh filename="collision/link5.stl"/>
      </geometry>
    </collision>
    <inertial>
      <origin rpy="0 0 0" xyz="-0.00828477 0.0439319 -0.0620007"/>
      <mass value="1.21201"/>
      <inertia ixx="0.035549" ixy="-0.002117" ixz="-0.004037" iyy="0.029474" iyz="0.000229" izz="0.008627"/>
    </inertial>
  </link>
  <joint name="panda_joint5" type="revolute">
    <safety_controller k_position="100.0" k_velocity="40.0" soft_lower_limit="-2.8973" soft_upper_limit="2.8973"/>
    <origin rpy="-1.5707963267948966 0 0" xyz="-0.0825 0.384 0"/>
    <parent link="panda_link4"/>
    <child link="panda_link5"/>
    <axis xyz="0 0 1"/>
    <limit acceleration="15" effort="12" lower="-2.9671" upper="2.9671" velocity="3"/>
    <dynamics D="1" K="7000" damping="0.003" friction="0.0" mu_coulomb="0" mu_viscous="16"/>
  </joint>
  <link name="panda_link6">
    <visual>
      <origin rpy="0 0 0" xyz="0 0 0"/>
      <geometry>
        <mesh filename="visual/link6.dae"/>
      </geometry>
    </visual>
    <collision>
      <origin rpy="0 0 0" xyz="0 0 0"/>
      <geometry>
        <mesh filename="collision/link6.stl"/>
      </geometry>
    </collision>
    <inertial>
      <origin rpy="0 0 0" xyz="0.0216331 0.0214695 -0.0144161"/>
      <mass value="1.65017"/>
      <inertia ixx="0.001964" ixy="0.000109" ixz="-0.001158" iyy="0.004354" iyz="0.000341" izz="0.005433"/>
    </inertial>
  </link>
  <joint name="panda_joint6" type="revolute">
    <safety_controller k_position="100.0" k_velocity="40.0" soft_lower_limit="-0.0175" soft_upper_limit="3.7525"/>
    <origin rpy="1.5707963267948966 0 0" xyz="0 0 0"/>
    <parent link="panda_link5"/>
    <child link="panda_link6"/>
    <axis xyz="0 0 1"/>
    <limit acceleration="20" effort="12" lower="-0.0873" upper="3.8223" velocity="3"/>
    <dynamics D="1" K="7000" damping="0.003" friction="0.0" mu_coulomb="0" mu_viscous="16"/>
  </joint>
  <link name="panda_link7">
    <visual>
      <origin rpy="0 0 0" xyz="0 0 0"/>
      <geometry>
        <mesh filename="visual/link7.dae"/>
      </geometry>
    </visual>
    <collision>
      <origin rpy="0 0 0" xyz="0 0 0"/>
      <geometry>
        <mesh filename="collision/link7.stl"/>
      </geometry>
    </collision>
    <inertial>
      <origin rpy="0 0 0" xyz="0.00431676 -0.000322275 0.0678681"/>
      <mass value="1.44666"/>
      <inertia ixx="0.016396" ixy="0.000394964" ixz="-0.000710116" iyy="0.0139734" iyz="-0.00105381" izz="0.00667531"/>
    </inertial>
  </link>
  <joint name="panda_joint7" type="revolute">
    <safety_controller k_position="100.0" k_velocity="40.0" soft_lower_limit="-2.8973" soft_upper_limit="2.8973"/>
    <origin rpy="1.5707963267948966 0 0" xyz="0.088 0 0"/>
    <parent link="panda_link6"/>
    <child link="panda_link7"/>
    <axis xyz="0 0 1"/>
    <limit acceleration="20" effort="12" lower="-2.9671" upper="2.9671" velocity="3"/>
    <dynamics D="1" K="7000" damping="0.003" friction="0.0" mu_coulomb="0" mu_viscous="16"/>
  </joint>
  <link name="panda_link8"/>
  <joint name="panda_joint8" type="fixed">
    <origin rpy="0 0 0" xyz="0 0 0.107"/>
    <parent link="panda_link7"/>
    <child link="panda_link8"/>
    <axis xyz="0 0 0"/>
  </joint>
  <joint name="panda_hand_joint" type="fixed">
    <parent link="panda_link8"/>
    <child link="panda_hand"/>
    <origin rpy="0 0 -0.7853981633974483" xyz="0 0 0"/>
  </joint>
  <link name="panda_hand">
    <visual>
      <geometry>
        <mesh filename="visual/hand.dae"/>
      </geometry>
    </visual>
    <collision>
      <origin rpy="0 1.5707963267948966 1.5707963267948966" xyz="0.0 0 0.0375"/>
      <geometry>
        <box size="0.055 0.04 0.198"/>
      </geometry>
    </collision>
    <inertial>
      <mass value="0.73"/>
      <origin xyz="-0.01 0 0.03"/>
      <inertia ixx="0.001" ixy="0" ixz="0" iyy="0.0025" iyz="0" izz="0.0017"/>
    </inertial>
  </link>
  <link name="panda_leftfinger">
    <inertial>
      <mass value="0.015"/>
      <inertia ixx="2.3749999999999997e-06" ixy="0" ixz="0" iyy="2.3749999999999997e-06" iyz="0" izz="7.5e-07"/>
    </inertial>
    <visual>
      <geometry>
        <mesh filename="visual/finger.dae"/>
      </geometry>
    </visual>
    <collision>
      <origin rpy="0 0 0" xyz="0 0.015 0.03"/>
      <geometry>
        <box size="0.03 0.005 0.047"/>
      </geometry>
    </collision>
    <collision>
      <origin rpy="0 0 0" xyz="0 0.007 0.045"/>
      <geometry>
        <box size="0.03 0.015 0.017"/>
      </geometry>
    </collision>
  </link>
  <link name="panda_rightfinger">
    <inertial>
      <mass value="0.015"/>
      <inertia ixx="2.3749999999999997e-06" ixy="0" ixz="0" iyy="2.3749999999999997e-06" iyz="0" izz="7.5e-07"/>
    </inertial>
    <visual>
      <origin rpy="0 0 3.141592653589793" xyz="0 0 0"/>
      <geometry>
        <mesh filename="visual/finger.dae"/>
      </geometry>
    </visual>
    <collision>
      <origin rpy="0 0 0" xyz="0 -0.015 0.03"/>
      <geometry>
        <box size="0.03 0.005 0.047"/>
      </geometry>
    </collision>
    <collision>
      <origin rpy="0 0 0" xyz="0 -0.007 0.045"/>
      <geometry>
        <box size="0.03 0.015 0.017"/>
      </geometry>
    </collision>
  </link>
  <gazebo reference="panda_leftfinger">
    <collision>
      <max_contacts>10</max_contacts>
      <surface>
        <contact>
          <ode>
            <!-- These two parameter need application specific tuning. -->
            <!-- Usually you want no "snap out" velocity and a generous -->
            <!-- penetration depth to keep the grasping stable -->
            <max_vel>0</max_vel>
            <min_depth>0.003</min_depth>
          </ode>
        </contact>
        <friction>
          <ode>
            <mu>1.13</mu>
            <mu2>1.13</mu2>
          </ode>
        </friction>
        <bounce/>
      </surface>
    </collision>
  </gazebo>
  <gazebo reference="panda_rightfinger">
    <collision>
      <max_contacts>10</max_contacts>
      <surface>
        <contact>
          <ode>
            <!-- These two parameter need application specific tuning. -->
            <!-- Usually you want no "snap out" velocity and a generous -->
            <!-- penetration depth to keep the grasping stable -->
            <max_vel>0</max_vel>
            <min_depth>0.003</min_depth>
          </ode>
        </contact>
        <friction>
          <ode>
            <mu>1.13</mu>
            <mu2>1.13</mu2>
          </ode>
        </friction>
        <bounce/>
      </surface>
    </collision>
  </gazebo>
  <joint name="panda_finger_joint1" type="prismatic">
    <parent link="panda_hand"/>
    <child link="panda_leftfinger"/>
    <origin rpy="0 0 0" xyz="0 0 0.0584"/>
    <axis xyz="0 1 0"/>
    <limit effort="20" lower="0.0" upper="0.04" velocity="0.2"/>
    <dynamics damping="0.3"/>
  </joint>
  <joint name="panda_finger_joint2" type="prismatic">
    <parent link="panda_hand"/>
    <child link="panda_rightfinger"/>
    <origin rpy="0 0 0" xyz="0 0 0.0584"/>
    <axis xyz="0 -1 0"/>
    <limit effort="20" lower="0.0" upper="0.04" velocity="0.2"/>
    <dynamics damping="0.3"/>
  </joint>
  <gazebo reference="panda_finger_joint1">
    <!-- Needed for ODE to output external wrenches on joints -->
    <provideFeedback>true</provideFeedback>
  </gazebo>
  <transmission name="panda_finger_joint1_transmission">
    <type>transmission_interface/SimpleTransmission</type>
    <joint name="panda_finger_joint1">
      <hardwareInterface>hardware_interface/EffortJointInterface</hardwareInterface>
    </joint>
    <actuator name="panda_finger_joint1_motor">
      <hardwareInterface>hardware_interface/EffortJointInterface</hardwareInterface>
    </actuator>
  </transmission>
  <gazebo reference="panda_finger_joint2">
    <!-- Needed for ODE to output external wrenches on joints -->
    <provideFeedback>true</provideFeedback>
  </gazebo>
  <transmission name="panda_finger_joint2_transmission">
    <type>transmission_interface/SimpleTransmission</type>
    <joint name="panda_finger_joint2">
      <hardwareInterface>hardware_interface/EffortJointInterface</hardwareInterface>
    </joint>
    <actuator name="panda_finger_joint2_motor">
      <hardwareInterface>hardware_interface/EffortJointInterface</hardwareInterface>
    </actuator>
  </transmission>
  <!-- Gazebo requires a joint to a link called "world" for statically mounted robots -->
  <link name="world"/>
  <joint name="world_joint" type="fixed">
    <origin rpy="0 0 0" xyz="0 0 0"/>
    <parent link="world"/>
    <child link="panda_link0"/>
  </joint>
  <gazebo reference="panda_joint1">
    <!-- Needed for ODE to output external wrenches on joints -->
    <provideFeedback>true</provideFeedback>
  </gazebo>
  <transmission name="panda_joint1_transmission">
    <type>transmission_interface/SimpleTransmission</type>
    <joint name="panda_joint1">
      <hardwareInterface>hardware_interface/EffortJointInterface</hardwareInterface>
    </joint>
    <actuator name="panda_joint1_motor">
      <hardwareInterface>hardware_interface/EffortJointInterface</hardwareInterface>
    </actuator>
  </transmission>
  <gazebo reference="panda_joint2">
    <!-- Needed for ODE to output external wrenches on joints -->
    <provideFeedback>true</provideFeedback>
  </gazebo>
  <transmission name="panda_joint2_transmission">
    <type>transmission_interface/SimpleTransmission</type>
    <joint name="panda_joint2">
      <hardwareInterface>hardware_interface/EffortJointInterface</hardwareInterface>
    </joint>
    <actuator name="panda_joint2_motor">
      <hardwareInterface>hardware_interface/EffortJointInterface</hardwareInterface>
    </actuator>
  </transmission>
  <gazebo reference="panda_joint3">
    <!-- Needed for ODE to output external wrenches on joints -->
    <provideFeedback>true</provideFeedback>
  </gazebo>
  <transmission name="panda_joint3_transmission">
    <type>transmission_interface/SimpleTransmission</type>
    <joint name="panda_joint3">
      <hardwareInterface>hardware_interface/EffortJointInterface</hardwareInterface>
    </joint>
    <actuator name="panda_joint3_motor">
      <hardwareInterface>hardware_interface/EffortJointInterface</hardwareInterface>
    </actuator>
  </transmission>
  <gazebo reference="panda_joint4">
    <!-- Needed for ODE to output external wrenches on joints -->
    <provideFeedback>true</provideFeedback>
  </gazebo>
  <transmission name="panda_joint4_transmission">
    <type>transmission_interface/SimpleTransmission</type>
    <joint name="panda_joint4">
      <hardwareInterface>hardware_interface/EffortJointInterface</hardwareInterface>
    </joint>
    <actuator name="panda_joint4_motor">
      <hardwareInterface>hardware_interface/EffortJointInterface</hardwareInterface>
    </actuator>
  </transmission>
  <gazebo reference="panda_joint5">
    <!-- Needed for ODE to output external wrenches on joints -->
    <provideFeedback>true</provideFeedback>
  </gazebo>
  <transmission name="panda_joint5_transmission">
    <type>transmission_interface/SimpleTransmission</type>
    <joint name="panda_joint5">
      <hardwareInterface>hardware_interface/EffortJointInterface</hardwareInterface>
    </joint>
    <actuator name="panda_joint5_motor">
      <hardwareInterface>hardware_interface/EffortJointInterface</hardwareInterface>
    </actuator>
  </transmission>
  <gazebo reference="panda_joint6">
    <!-- Needed for ODE to output external wrenches on joints -->
    <provideFeedback>true</provideFeedback>
  </gazebo>
  <transmission name="panda_joint6_transmission">
    <type>transmission_interface/SimpleTransmission</type>
    <joint name="panda_joint6">
      <hardwareInterface>hardware_interface/EffortJointInterface</hardwareInterface>
    </joint>
    <actuator name="panda_joint6_motor">
      <hardwareInterface>hardware_interface/EffortJointInterface</hardwareInterface>
    </actuator>
  </transmission>
  <gazebo reference="panda_joint7">
    <!-- Needed for ODE to output external wrenches on joints -->
    <provideFeedback>true</provideFeedback>
  </gazebo>
  <transmission name="panda_joint7_transmission">
    <type>transmission_interface/SimpleTransmission</type>
    <joint name="panda_joint7">
      <hardwareInterface>hardware_interface/EffortJointInterface</hardwareInterface>
    </joint>
    <actuator name="panda_joint7_motor">
      <hardwareInterface>hardware_interface/EffortJointInterface</hardwareInterface>
    </actuator>
  </transmission>
  <transmission name="panda_franka_state">
    <type>franka_hw/FrankaStateInterface</type>
    <joint name="panda_joint1">
      <hardwareInterface>franka_hw/FrankaStateInterface</hardwareInterface>
    </joint>
    <joint name="panda_joint2">
      <hardwareInterface>franka_hw/FrankaStateInterface</hardwareInterface>
    </joint>
    <joint name="panda_joint3">
      <hardwareInterface>franka_hw/FrankaStateInterface</hardwareInterface>
    </joint>
    <joint name="panda_joint4">
      <hardwareInterface>franka_hw/FrankaStateInterface</hardwareInterface>
    </joint>
    <joint name="panda_joint5">
      <hardwareInterface>franka_hw/FrankaStateInterface</hardwareInterface>
    </joint>
    <joint name="panda_joint6">
      <hardwareInterface>franka_hw/FrankaStateInterface</hardwareInterface>
    </joint>
    <joint name="panda_joint7">
      <hardwareInterface>franka_hw/FrankaStateInterface</hardwareInterface>
    </joint>
    <actuator name="panda_motor1">
      <hardwareInterface>franka_hw/FrankaStateInterface</hardwareInterface>
    </actuator>
    <actuator name="panda_motor2">
      <hardwareInterface>franka_hw/FrankaStateInterface</hardwareInterface>
    </actuator>
    <actuator name="panda_motor3">
      <hardwareInterface>franka_hw/FrankaStateInterface</hardwareInterface>
    </actuator>
    <actuator name="panda_motor4">
      <hardwareInterface>franka_hw/FrankaStateInterface</hardwareInterface>
    </actuator>
    <actuator name="panda_motor5">
      <hardwareInterface>franka_hw/FrankaStateInterface</hardwareInterface>
    </actuator>
    <actuator name="panda_motor6">
      <hardwareInterface>franka_hw/FrankaStateInterface</hardwareInterface>
    </actuator>
    <actuator name="panda_motor7">
      <hardwareInterface>franka_hw/FrankaStateInterface</hardwareInterface>
    </actuator>
  </transmission>
  <transmission name="panda_franka_model">
    <type>franka_hw/FrankaModelInterface</type>
    <joint name="panda_joint1">
      <role>root</role>
      <hardwareInterface>franka_hw/FrankaModelInterface</hardwareInterface>
    </joint>
    <joint name="panda_joint8">
      <role>tip</role>
      <hardwareInterface>franka_hw/FrankaModelInterface</hardwareInterface>
    </joint>
    <actuator name="panda_joint1_motor_root">
      <hardwareInterface>franka_hw/FrankaModelInterface</hardwareInterface>
    </actuator>
    <actuator name="panda_joint8_motor_tip">
      <hardwareInterface>franka_hw/FrankaModelInterface</hardwareInterface>
    </actuator>
  </transmission>
  <gazebo>
    <self_collide>true</self_collide>
  </gazebo>
</robot>

